{
 "cells": [
  {
   "cell_type": "code",
   "execution_count": 1,
   "metadata": {},
   "outputs": [],
   "source": [
    "%reload_ext autoreload\n",
    "%autoreload 2\n",
    "import json\n",
    "import logging\n",
    "import numpy as np\n",
    "import pandas as pd\n",
    "from pyeed import Pyeed\n",
    "import matplotlib.pyplot as plt\n",
    "import itertools\n",
    "from pyeed.analysis.embedding_analysis import EmbeddingTool\n",
    "from scipy.spatial.distance import pdist, squareform\n",
    "from neomodel import db\n",
    "import rich"
   ]
  },
  {
   "cell_type": "code",
   "execution_count": 2,
   "metadata": {},
   "outputs": [],
   "source": [
    "from mdmodels import DataModel\n",
    "from mdmodels.graph import connect_to_neo4j, generate_neomodel"
   ]
  },
  {
   "cell_type": "code",
   "execution_count": 3,
   "metadata": {},
   "outputs": [
    {
     "name": "stdout",
     "output_type": "stream",
     "text": [
      "Pyeed Graph Object Mapping constraints not defined. Use _install_labels() to set up model constraints.\n",
      "ðŸ“¡ Connected to database.\n",
      "All data has been wiped from the database.\n",
      "Connecting to bolt://neo4j:12345678@127.0.0.1:7687\n",
      "Dropping constraints...\n",
      "\n",
      "Dropping indexes...\n",
      "\n",
      "All constraints and indexes have been removed from the database.\n"
     ]
    }
   ],
   "source": [
    "uri = \"bolt://127.0.0.1:7687\"\n",
    "user = \"neo4j\"\n",
    "password = \"12345678\"\n",
    "\n",
    "eedb = Pyeed(uri, user=user, password=password)\n",
    "\n",
    "eedb.db.wipe_database('2024-12-08')\n",
    "eedb.db.remove_db_constraints(user=user, password=password)"
   ]
  },
  {
   "cell_type": "code",
   "execution_count": null,
   "metadata": {},
   "outputs": [],
   "source": []
  },
  {
   "cell_type": "code",
   "execution_count": 3,
   "metadata": {},
   "outputs": [
    {
     "ename": "NameError",
     "evalue": "name 'connect_to_neo4j' is not defined",
     "output_type": "error",
     "traceback": [
      "\u001b[0;31m---------------------------------------------------------------------------\u001b[0m",
      "\u001b[0;31mNameError\u001b[0m                                 Traceback (most recent call last)",
      "Cell \u001b[0;32mIn[3], line 2\u001b[0m\n\u001b[1;32m      1\u001b[0m \u001b[38;5;66;03m# Step 1: Connect to Neo4J\u001b[39;00m\n\u001b[0;32m----> 2\u001b[0m \u001b[43mconnect_to_neo4j\u001b[49m(\n\u001b[1;32m      3\u001b[0m     host\u001b[38;5;241m=\u001b[39m\u001b[38;5;124m\"\u001b[39m\u001b[38;5;124mlocalhost\u001b[39m\u001b[38;5;124m\"\u001b[39m,\n\u001b[1;32m      4\u001b[0m     user\u001b[38;5;241m=\u001b[39m\u001b[38;5;124m\"\u001b[39m\u001b[38;5;124mneo4j\u001b[39m\u001b[38;5;124m\"\u001b[39m,\n\u001b[1;32m      5\u001b[0m     password\u001b[38;5;241m=\u001b[39m\u001b[38;5;124m\"\u001b[39m\u001b[38;5;124m12345678\u001b[39m\u001b[38;5;124m\"\u001b[39m,\n\u001b[1;32m      6\u001b[0m     port\u001b[38;5;241m=\u001b[39m\u001b[38;5;241m7687\u001b[39m\n\u001b[1;32m      7\u001b[0m )\n\u001b[1;32m      9\u001b[0m \u001b[38;5;66;03m# Clear the database\u001b[39;00m\n\u001b[1;32m     10\u001b[0m db\u001b[38;5;241m.\u001b[39mcypher_query(\u001b[38;5;124m\"\u001b[39m\u001b[38;5;124mMATCH (n) DETACH DELETE n\u001b[39m\u001b[38;5;124m\"\u001b[39m)\n",
      "\u001b[0;31mNameError\u001b[0m: name 'connect_to_neo4j' is not defined"
     ]
    }
   ],
   "source": [
    "# Step 1: Connect to Neo4J\n",
    "connect_to_neo4j(\n",
    "    host=\"localhost\",\n",
    "    user=\"neo4j\",\n",
    "    password=\"12345678\",\n",
    "    port=7687\n",
    ")\n",
    "\n",
    "# Clear the database\n",
    "db.cypher_query(\"MATCH (n) DETACH DELETE n\")"
   ]
  },
  {
   "cell_type": "code",
   "execution_count": 5,
   "metadata": {},
   "outputs": [
    {
     "name": "stderr",
     "output_type": "stream",
     "text": [
      "thread '<unnamed>' panicked at src/bindings/python.rs:58:74:\n",
      "called `Result::unwrap()` on an `Err` value: Validator { is_valid: false, errors: [ValidationError { message: \"Property Relationship is defined more than once.\", object: Some(\"Relationships\"), attribute: Some(\"Relationship\"), location: \"Global\", error_type: DuplicateError }, ValidationError { message: \"Property Description is defined more than once.\", object: Some(\"Relationships\"), attribute: Some(\"Description\"), location: \"Global\", error_type: DuplicateError }, ValidationError { message: \"Property Attributes is defined more than once.\", object: Some(\"Relationships\"), attribute: Some(\"Attributes\"), location: \"Global\", error_type: DuplicateError }, ValidationError { message: \"Property positions is defined more than once.\", object: Some(\"Relationships\"), attribute: Some(\"positions\"), location: \"Global\", error_type: DuplicateError }, ValidationError { message: \"Property Relationship has no type specified.\", object: Some(\"Relationships\"), attribute: Some(\"Relationship\"), location: \"Global\", error_type: TypeError }, ValidationError { message: \"Property Description has no type specified.\", object: Some(\"Relationships\"), attribute: Some(\"Description\"), location: \"Global\", error_type: TypeError }, ValidationError { message: \"Property Relationship has no type specified.\", object: Some(\"Relationships\"), attribute: Some(\"Relationship\"), location: \"Global\", error_type: TypeError }, ValidationError { message: \"Property Description has no type specified.\", object: Some(\"Relationships\"), attribute: Some(\"Description\"), location: \"Global\", error_type: TypeError }, ValidationError { message: \"Property Relationship has no type specified.\", object: Some(\"Relationships\"), attribute: Some(\"Relationship\"), location: \"Global\", error_type: TypeError }, ValidationError { message: \"Property Attributes has no type specified.\", object: Some(\"Relationships\"), attribute: Some(\"Attributes\"), location: \"Global\", error_type: TypeError }, ValidationError { message: \"Property positions has no type specified.\", object: Some(\"Relationships\"), attribute: Some(\"positions\"), location: \"Global\", error_type: TypeError }, ValidationError { message: \"Property Relationship has no type specified.\", object: Some(\"Relationships\"), attribute: Some(\"Relationship\"), location: \"Global\", error_type: TypeError }, ValidationError { message: \"Property Attributes has no type specified.\", object: Some(\"Relationships\"), attribute: Some(\"Attributes\"), location: \"Global\", error_type: TypeError }, ValidationError { message: \"Property start has no type specified.\", object: Some(\"Relationships\"), attribute: Some(\"start\"), location: \"Global\", error_type: TypeError }, ValidationError { message: \"Property end has no type specified.\", object: Some(\"Relationships\"), attribute: Some(\"end\"), location: \"Global\", error_type: TypeError }, ValidationError { message: \"Property Relationship has no type specified.\", object: Some(\"Relationships\"), attribute: Some(\"Relationship\"), location: \"Global\", error_type: TypeError }, ValidationError { message: \"Property Attributes has no type specified.\", object: Some(\"Relationships\"), attribute: Some(\"Attributes\"), location: \"Global\", error_type: TypeError }, ValidationError { message: \"Property positions has no type specified.\", object: Some(\"Relationships\"), attribute: Some(\"positions\"), location: \"Global\", error_type: TypeError }, ValidationError { message: \"Property Relationship has no type specified.\", object: Some(\"Ontology\"), attribute: Some(\"Relationship\"), location: \"Global\", error_type: TypeError }, ValidationError { message: \"Property Attributes has no type specified.\", object: Some(\"Ontology\"), attribute: Some(\"Attributes\"), location: \"Global\", error_type: TypeError }, ValidationError { message: \"Property ontology_id has no type specified.\", object: Some(\"Ontology\"), attribute: Some(\"ontology_id\"), location: \"Global\", error_type: TypeError }, ValidationError { message: \"Property label has no type specified.\", object: Some(\"Ontology\"), attribute: Some(\"label\"), location: \"Global\", error_type: TypeError }] }\n",
      "note: run with `RUST_BACKTRACE=1` environment variable to display a backtrace\n"
     ]
    },
    {
     "ename": "PanicException",
     "evalue": "called `Result::unwrap()` on an `Err` value: Validator { is_valid: false, errors: [ValidationError { message: \"Property Relationship is defined more than once.\", object: Some(\"Relationships\"), attribute: Some(\"Relationship\"), location: \"Global\", error_type: DuplicateError }, ValidationError { message: \"Property Description is defined more than once.\", object: Some(\"Relationships\"), attribute: Some(\"Description\"), location: \"Global\", error_type: DuplicateError }, ValidationError { message: \"Property Attributes is defined more than once.\", object: Some(\"Relationships\"), attribute: Some(\"Attributes\"), location: \"Global\", error_type: DuplicateError }, ValidationError { message: \"Property positions is defined more than once.\", object: Some(\"Relationships\"), attribute: Some(\"positions\"), location: \"Global\", error_type: DuplicateError }, ValidationError { message: \"Property Relationship has no type specified.\", object: Some(\"Relationships\"), attribute: Some(\"Relationship\"), location: \"Global\", error_type: TypeError }, ValidationError { message: \"Property Description has no type specified.\", object: Some(\"Relationships\"), attribute: Some(\"Description\"), location: \"Global\", error_type: TypeError }, ValidationError { message: \"Property Relationship has no type specified.\", object: Some(\"Relationships\"), attribute: Some(\"Relationship\"), location: \"Global\", error_type: TypeError }, ValidationError { message: \"Property Description has no type specified.\", object: Some(\"Relationships\"), attribute: Some(\"Description\"), location: \"Global\", error_type: TypeError }, ValidationError { message: \"Property Relationship has no type specified.\", object: Some(\"Relationships\"), attribute: Some(\"Relationship\"), location: \"Global\", error_type: TypeError }, ValidationError { message: \"Property Attributes has no type specified.\", object: Some(\"Relationships\"), attribute: Some(\"Attributes\"), location: \"Global\", error_type: TypeError }, ValidationError { message: \"Property positions has no type specified.\", object: Some(\"Relationships\"), attribute: Some(\"positions\"), location: \"Global\", error_type: TypeError }, ValidationError { message: \"Property Relationship has no type specified.\", object: Some(\"Relationships\"), attribute: Some(\"Relationship\"), location: \"Global\", error_type: TypeError }, ValidationError { message: \"Property Attributes has no type specified.\", object: Some(\"Relationships\"), attribute: Some(\"Attributes\"), location: \"Global\", error_type: TypeError }, ValidationError { message: \"Property start has no type specified.\", object: Some(\"Relationships\"), attribute: Some(\"start\"), location: \"Global\", error_type: TypeError }, ValidationError { message: \"Property end has no type specified.\", object: Some(\"Relationships\"), attribute: Some(\"end\"), location: \"Global\", error_type: TypeError }, ValidationError { message: \"Property Relationship has no type specified.\", object: Some(\"Relationships\"), attribute: Some(\"Relationship\"), location: \"Global\", error_type: TypeError }, ValidationError { message: \"Property Attributes has no type specified.\", object: Some(\"Relationships\"), attribute: Some(\"Attributes\"), location: \"Global\", error_type: TypeError }, ValidationError { message: \"Property positions has no type specified.\", object: Some(\"Relationships\"), attribute: Some(\"positions\"), location: \"Global\", error_type: TypeError }, ValidationError { message: \"Property Relationship has no type specified.\", object: Some(\"Ontology\"), attribute: Some(\"Relationship\"), location: \"Global\", error_type: TypeError }, ValidationError { message: \"Property Attributes has no type specified.\", object: Some(\"Ontology\"), attribute: Some(\"Attributes\"), location: \"Global\", error_type: TypeError }, ValidationError { message: \"Property ontology_id has no type specified.\", object: Some(\"Ontology\"), attribute: Some(\"ontology_id\"), location: \"Global\", error_type: TypeError }, ValidationError { message: \"Property label has no type specified.\", object: Some(\"Ontology\"), attribute: Some(\"label\"), location: \"Global\", error_type: TypeError }] }",
     "output_type": "error",
     "traceback": [
      "\u001b[0;31m---------------------------------------------------------------------------\u001b[0m",
      "\u001b[0;31mPanicException\u001b[0m                            Traceback (most recent call last)",
      "Cell \u001b[0;32mIn[5], line 2\u001b[0m\n\u001b[1;32m      1\u001b[0m \u001b[38;5;66;03m# Step 2: Generate neomodel types\u001b[39;00m\n\u001b[0;32m----> 2\u001b[0m types \u001b[38;5;241m=\u001b[39m \u001b[43mgenerate_neomodel\u001b[49m\u001b[43m(\u001b[49m\u001b[43mpath\u001b[49m\u001b[38;5;241;43m=\u001b[39;49m\u001b[38;5;124;43m\"\u001b[39;49m\u001b[38;5;124;43mmodel_pyeed.md\u001b[39;49m\u001b[38;5;124;43m\"\u001b[39;49m\u001b[43m)\u001b[49m\n\u001b[1;32m      3\u001b[0m rich\u001b[38;5;241m.\u001b[39mprint(types)\n",
      "File \u001b[0;32m~/Niklas/py-mdmodels/mdmodels/graph/create.py:56\u001b[0m, in \u001b[0;36mgenerate_neomodel\u001b[0;34m(path, content)\u001b[0m\n\u001b[1;32m     54\u001b[0m     model \u001b[38;5;241m=\u001b[39m DataModel\u001b[38;5;241m.\u001b[39mfrom_markdown_string(content)\u001b[38;5;241m.\u001b[39mmodel\n\u001b[1;32m     55\u001b[0m \u001b[38;5;28;01melif\u001b[39;00m path:\n\u001b[0;32m---> 56\u001b[0m     model \u001b[38;5;241m=\u001b[39m \u001b[43mDataModel\u001b[49m\u001b[38;5;241;43m.\u001b[39;49m\u001b[43mfrom_markdown\u001b[49m\u001b[43m(\u001b[49m\u001b[38;5;28;43mstr\u001b[39;49m\u001b[43m(\u001b[49m\u001b[43mpath\u001b[49m\u001b[43m)\u001b[49m\u001b[43m)\u001b[49m\u001b[38;5;241m.\u001b[39mmodel\n\u001b[1;32m     57\u001b[0m \u001b[38;5;28;01melse\u001b[39;00m:\n\u001b[1;32m     58\u001b[0m     \u001b[38;5;28;01mraise\u001b[39;00m \u001b[38;5;167;01mValueError\u001b[39;00m(\u001b[38;5;124m\"\u001b[39m\u001b[38;5;124mEither path or content must be provided.\u001b[39m\u001b[38;5;124m\"\u001b[39m)\n",
      "\u001b[0;31mPanicException\u001b[0m: called `Result::unwrap()` on an `Err` value: Validator { is_valid: false, errors: [ValidationError { message: \"Property Relationship is defined more than once.\", object: Some(\"Relationships\"), attribute: Some(\"Relationship\"), location: \"Global\", error_type: DuplicateError }, ValidationError { message: \"Property Description is defined more than once.\", object: Some(\"Relationships\"), attribute: Some(\"Description\"), location: \"Global\", error_type: DuplicateError }, ValidationError { message: \"Property Attributes is defined more than once.\", object: Some(\"Relationships\"), attribute: Some(\"Attributes\"), location: \"Global\", error_type: DuplicateError }, ValidationError { message: \"Property positions is defined more than once.\", object: Some(\"Relationships\"), attribute: Some(\"positions\"), location: \"Global\", error_type: DuplicateError }, ValidationError { message: \"Property Relationship has no type specified.\", object: Some(\"Relationships\"), attribute: Some(\"Relationship\"), location: \"Global\", error_type: TypeError }, ValidationError { message: \"Property Description has no type specified.\", object: Some(\"Relationships\"), attribute: Some(\"Description\"), location: \"Global\", error_type: TypeError }, ValidationError { message: \"Property Relationship has no type specified.\", object: Some(\"Relationships\"), attribute: Some(\"Relationship\"), location: \"Global\", error_type: TypeError }, ValidationError { message: \"Property Description has no type specified.\", object: Some(\"Relationships\"), attribute: Some(\"Description\"), location: \"Global\", error_type: TypeError }, ValidationError { message: \"Property Relationship has no type specified.\", object: Some(\"Relationships\"), attribute: Some(\"Relationship\"), location: \"Global\", error_type: TypeError }, ValidationError { message: \"Property Attributes has no type specified.\", object: Some(\"Relationships\"), attribute: Some(\"Attributes\"), location: \"Global\", error_type: TypeError }, ValidationError { message: \"Property positions has no type specified.\", object: Some(\"Relationships\"), attribute: Some(\"positions\"), location: \"Global\", error_type: TypeError }, ValidationError { message: \"Property Relationship has no type specified.\", object: Some(\"Relationships\"), attribute: Some(\"Relationship\"), location: \"Global\", error_type: TypeError }, ValidationError { message: \"Property Attributes has no type specified.\", object: Some(\"Relationships\"), attribute: Some(\"Attributes\"), location: \"Global\", error_type: TypeError }, ValidationError { message: \"Property start has no type specified.\", object: Some(\"Relationships\"), attribute: Some(\"start\"), location: \"Global\", error_type: TypeError }, ValidationError { message: \"Property end has no type specified.\", object: Some(\"Relationships\"), attribute: Some(\"end\"), location: \"Global\", error_type: TypeError }, ValidationError { message: \"Property Relationship has no type specified.\", object: Some(\"Relationships\"), attribute: Some(\"Relationship\"), location: \"Global\", error_type: TypeError }, ValidationError { message: \"Property Attributes has no type specified.\", object: Some(\"Relationships\"), attribute: Some(\"Attributes\"), location: \"Global\", error_type: TypeError }, ValidationError { message: \"Property positions has no type specified.\", object: Some(\"Relationships\"), attribute: Some(\"positions\"), location: \"Global\", error_type: TypeError }, ValidationError { message: \"Property Relationship has no type specified.\", object: Some(\"Ontology\"), attribute: Some(\"Relationship\"), location: \"Global\", error_type: TypeError }, ValidationError { message: \"Property Attributes has no type specified.\", object: Some(\"Ontology\"), attribute: Some(\"Attributes\"), location: \"Global\", error_type: TypeError }, ValidationError { message: \"Property ontology_id has no type specified.\", object: Some(\"Ontology\"), attribute: Some(\"ontology_id\"), location: \"Global\", error_type: TypeError }, ValidationError { message: \"Property label has no type specified.\", object: Some(\"Ontology\"), attribute: Some(\"label\"), location: \"Global\", error_type: TypeError }] }"
     ]
    }
   ],
   "source": [
    "# Step 2: Generate neomodel types\n",
    "types = generate_neomodel(path=\"model_pyeed.md\")\n",
    "rich.print(types)"
   ]
  },
  {
   "cell_type": "code",
   "execution_count": null,
   "metadata": {},
   "outputs": [],
   "source": []
  },
  {
   "cell_type": "code",
   "execution_count": null,
   "metadata": {},
   "outputs": [],
   "source": []
  },
  {
   "cell_type": "code",
   "execution_count": null,
   "metadata": {},
   "outputs": [],
   "source": []
  },
  {
   "cell_type": "code",
   "execution_count": null,
   "metadata": {},
   "outputs": [],
   "source": []
  },
  {
   "cell_type": "code",
   "execution_count": 29,
   "metadata": {},
   "outputs": [],
   "source": [
    "# Step 3: Create a new node\n",
    "Molecule = types[\"Molecule\"]\n",
    "Reaction = types[\"Reaction\"]\n",
    "\n",
    "reaction = Reaction(name=\"Reaction\").save()\n",
    "substrate = Molecule(identifier=\"Substrate\", name=\"Substrate\").save()\n",
    "product = Molecule(identifier=\"Product\", name=\"Product\").save()"
   ]
  },
  {
   "cell_type": "code",
   "execution_count": 30,
   "metadata": {},
   "outputs": [
    {
     "data": {
      "text/plain": [
       "True"
      ]
     },
     "execution_count": 30,
     "metadata": {},
     "output_type": "execute_result"
    }
   ],
   "source": [
    "# Step 4: Create a relationship\n",
    "reaction.educts.connect(substrate)\n",
    "reaction.products.connect(product)"
   ]
  },
  {
   "cell_type": "code",
   "execution_count": 31,
   "metadata": {},
   "outputs": [],
   "source": [
    "# Step 5: Add out of schema relationship\n",
    "reaction_2 = Reaction(name=\"Related Reaction\").save()\n",
    "\n",
    "reaction.dyn_connect(reaction_2, \"RELATED\", {\"has_same_kinetics\": True})"
   ]
  },
  {
   "cell_type": "code",
   "execution_count": null,
   "metadata": {},
   "outputs": [],
   "source": []
  },
  {
   "cell_type": "code",
   "execution_count": 2,
   "metadata": {},
   "outputs": [
    {
     "name": "stdout",
     "output_type": "stream",
     "text": [
      "your_secret_value\n"
     ]
    }
   ],
   "source": [
    "from dotenv import load_dotenv\n",
    "import os\n",
    "\n",
    "load_dotenv()  # Load variables from .env\n",
    "secret_key = os.getenv(\"MY_SECRET_KEY\")\n",
    "if secret_key is None:\n",
    "    raise ValueError(\"MY_SECRET_KEY is not set in the .env file.\")\n",
    "print(secret_key)\n"
   ]
  },
  {
   "cell_type": "code",
   "execution_count": null,
   "metadata": {},
   "outputs": [],
   "source": []
  },
  {
   "cell_type": "code",
   "execution_count": 1,
   "metadata": {},
   "outputs": [
    {
     "name": "stderr",
     "output_type": "stream",
     "text": [
      "/home/nab/anaconda3/envs/pyeed_niklas/lib/python3.12/site-packages/tqdm/auto.py:21: TqdmWarning: IProgress not found. Please update jupyter and ipywidgets. See https://ipywidgets.readthedocs.io/en/stable/user_install.html\n",
      "  from .autonotebook import tqdm as notebook_tqdm\n",
      "\u001b[32m2025-01-17 10:05:43.675\u001b[0m | \u001b[1mINFO    \u001b[0m | \u001b[36mpyeed.main\u001b[0m:\u001b[36mbackup_database\u001b[0m:\u001b[36m381\u001b[0m - \u001b[1mStopping Neo4j database...\u001b[0m\n",
      "\u001b[32m2025-01-17 10:05:43.689\u001b[0m | \u001b[31m\u001b[1mERROR   \u001b[0m | \u001b[36mpyeed.main\u001b[0m:\u001b[36m_run_command\u001b[0m:\u001b[36m353\u001b[0m - \u001b[31m\u001b[1mError: sudo: a terminal is required to read the password; either use the -S option to read from standard input or configure an askpass helper\n",
      "sudo: a password is required\n",
      "\u001b[0m\n"
     ]
    },
    {
     "name": "stdout",
     "output_type": "stream",
     "text": [
      "Pyeed Graph Object Mapping constraints not defined. Use _install_labels() to set up model constraints.\n",
      "ðŸ“¡ Connected to database.\n"
     ]
    },
    {
     "ename": "CalledProcessError",
     "evalue": "Command 'sudo docker exec neo4j-niklas-tem-main neo4j-admin server stop' returned non-zero exit status 1.",
     "output_type": "error",
     "traceback": [
      "\u001b[0;31m---------------------------------------------------------------------------\u001b[0m",
      "\u001b[0;31mCalledProcessError\u001b[0m                        Traceback (most recent call last)",
      "Cell \u001b[0;32mIn[1], line 5\u001b[0m\n\u001b[1;32m      1\u001b[0m \u001b[38;5;28;01mfrom\u001b[39;00m \u001b[38;5;21;01mpyeed\u001b[39;00m \u001b[38;5;28;01mimport\u001b[39;00m Pyeed\n\u001b[1;32m      3\u001b[0m eedb \u001b[38;5;241m=\u001b[39m Pyeed(\u001b[38;5;124m'\u001b[39m\u001b[38;5;124mbolt://127.0.0.1:2123\u001b[39m\u001b[38;5;124m'\u001b[39m, user\u001b[38;5;241m=\u001b[39m\u001b[38;5;124m'\u001b[39m\u001b[38;5;124mneo4j\u001b[39m\u001b[38;5;124m'\u001b[39m, password\u001b[38;5;241m=\u001b[39m\u001b[38;5;124m'\u001b[39m\u001b[38;5;124m1234567890\u001b[39m\u001b[38;5;124m'\u001b[39m)\n\u001b[0;32m----> 5\u001b[0m \u001b[43meedb\u001b[49m\u001b[38;5;241;43m.\u001b[39;49m\u001b[43mbackup_database\u001b[49m\u001b[43m(\u001b[49m\u001b[43mbackup_dir\u001b[49m\u001b[38;5;241;43m=\u001b[39;49m\u001b[38;5;124;43m'\u001b[39;49m\u001b[38;5;124;43m'\u001b[39;49m\u001b[43m,\u001b[49m\u001b[43m \u001b[49m\u001b[43mcontainer_name\u001b[49m\u001b[38;5;241;43m=\u001b[39;49m\u001b[38;5;124;43m'\u001b[39;49m\u001b[38;5;124;43mneo4j-niklas-tem-main\u001b[39;49m\u001b[38;5;124;43m'\u001b[39;49m\u001b[43m,\u001b[49m\u001b[43m \u001b[49m\u001b[43mimport_dir\u001b[49m\u001b[38;5;241;43m=\u001b[39;49m\u001b[38;5;124;43m'\u001b[39;49m\u001b[38;5;124;43mimport\u001b[39;49m\u001b[38;5;124;43m'\u001b[39;49m\u001b[43m)\u001b[49m\n",
      "File \u001b[0;32m~/Niklas/pyeed/src/pyeed/main.py:382\u001b[0m, in \u001b[0;36mPyeed.backup_database\u001b[0;34m(self, backup_dir, container_name, import_dir)\u001b[0m\n\u001b[1;32m    380\u001b[0m \u001b[38;5;66;03m# Stop the database\u001b[39;00m\n\u001b[1;32m    381\u001b[0m logger\u001b[38;5;241m.\u001b[39minfo(\u001b[38;5;124m\"\u001b[39m\u001b[38;5;124mStopping Neo4j database...\u001b[39m\u001b[38;5;124m\"\u001b[39m)\n\u001b[0;32m--> 382\u001b[0m \u001b[38;5;28;43mself\u001b[39;49m\u001b[38;5;241;43m.\u001b[39;49m\u001b[43m_run_command\u001b[49m\u001b[43m(\u001b[49m\u001b[38;5;124;43mf\u001b[39;49m\u001b[38;5;124;43m\"\u001b[39;49m\u001b[38;5;124;43msudo docker exec \u001b[39;49m\u001b[38;5;132;43;01m{\u001b[39;49;00m\u001b[43mcontainer_name\u001b[49m\u001b[38;5;132;43;01m}\u001b[39;49;00m\u001b[38;5;124;43m neo4j-admin server stop\u001b[39;49m\u001b[38;5;124;43m\"\u001b[39;49m\u001b[43m)\u001b[49m\n\u001b[1;32m    384\u001b[0m \u001b[38;5;66;03m# Create backup\u001b[39;00m\n\u001b[1;32m    385\u001b[0m command \u001b[38;5;241m=\u001b[39m \u001b[38;5;124mf\u001b[39m\u001b[38;5;124m\"\u001b[39m\u001b[38;5;124msudo docker exec \u001b[39m\u001b[38;5;132;01m{\u001b[39;00mcontainer_name\u001b[38;5;132;01m}\u001b[39;00m\u001b[38;5;124m neo4j-admin database dump --verbose --to-path=/import/ --overwrite-destination=true neo4j\u001b[39m\u001b[38;5;124m\"\u001b[39m\n",
      "File \u001b[0;32m~/Niklas/pyeed/src/pyeed/main.py:350\u001b[0m, in \u001b[0;36mPyeed._run_command\u001b[0;34m(self, command)\u001b[0m\n\u001b[1;32m    348\u001b[0m \u001b[38;5;250m\u001b[39m\u001b[38;5;124;03m\"\"\"Run a shell command and handle errors.\"\"\"\u001b[39;00m\n\u001b[1;32m    349\u001b[0m \u001b[38;5;28;01mtry\u001b[39;00m:\n\u001b[0;32m--> 350\u001b[0m     result \u001b[38;5;241m=\u001b[39m \u001b[43msubprocess\u001b[49m\u001b[38;5;241;43m.\u001b[39;49m\u001b[43mrun\u001b[49m\u001b[43m(\u001b[49m\u001b[43mcommand\u001b[49m\u001b[43m,\u001b[49m\u001b[43m \u001b[49m\u001b[43mshell\u001b[49m\u001b[38;5;241;43m=\u001b[39;49m\u001b[38;5;28;43;01mTrue\u001b[39;49;00m\u001b[43m,\u001b[49m\u001b[43m \u001b[49m\u001b[43mcheck\u001b[49m\u001b[38;5;241;43m=\u001b[39;49m\u001b[38;5;28;43;01mTrue\u001b[39;49;00m\u001b[43m,\u001b[49m\u001b[43m \u001b[49m\u001b[43mcapture_output\u001b[49m\u001b[38;5;241;43m=\u001b[39;49m\u001b[38;5;28;43;01mTrue\u001b[39;49;00m\u001b[43m,\u001b[49m\u001b[43m \u001b[49m\u001b[43mtext\u001b[49m\u001b[38;5;241;43m=\u001b[39;49m\u001b[38;5;28;43;01mTrue\u001b[39;49;00m\u001b[43m)\u001b[49m\n\u001b[1;32m    351\u001b[0m     logger\u001b[38;5;241m.\u001b[39minfo(result\u001b[38;5;241m.\u001b[39mstdout)\n\u001b[1;32m    352\u001b[0m \u001b[38;5;28;01mexcept\u001b[39;00m subprocess\u001b[38;5;241m.\u001b[39mCalledProcessError \u001b[38;5;28;01mas\u001b[39;00m e:\n",
      "File \u001b[0;32m~/anaconda3/envs/pyeed_niklas/lib/python3.12/subprocess.py:571\u001b[0m, in \u001b[0;36mrun\u001b[0;34m(input, capture_output, timeout, check, *popenargs, **kwargs)\u001b[0m\n\u001b[1;32m    569\u001b[0m     retcode \u001b[38;5;241m=\u001b[39m process\u001b[38;5;241m.\u001b[39mpoll()\n\u001b[1;32m    570\u001b[0m     \u001b[38;5;28;01mif\u001b[39;00m check \u001b[38;5;129;01mand\u001b[39;00m retcode:\n\u001b[0;32m--> 571\u001b[0m         \u001b[38;5;28;01mraise\u001b[39;00m CalledProcessError(retcode, process\u001b[38;5;241m.\u001b[39margs,\n\u001b[1;32m    572\u001b[0m                                  output\u001b[38;5;241m=\u001b[39mstdout, stderr\u001b[38;5;241m=\u001b[39mstderr)\n\u001b[1;32m    573\u001b[0m \u001b[38;5;28;01mreturn\u001b[39;00m CompletedProcess(process\u001b[38;5;241m.\u001b[39margs, retcode, stdout, stderr)\n",
      "\u001b[0;31mCalledProcessError\u001b[0m: Command 'sudo docker exec neo4j-niklas-tem-main neo4j-admin server stop' returned non-zero exit status 1."
     ]
    }
   ],
   "source": [
    "from pyeed import Pyeed\n",
    "\n",
    "eedb = Pyeed('bolt://127.0.0.1:2123', user='neo4j', password='1234567890')\n",
    "\n",
    "eedb.backup_database(backup_dir='', container_name='neo4j-niklas-tem-main', import_dir='import')\n"
   ]
  },
  {
   "cell_type": "code",
   "execution_count": 25,
   "metadata": {},
   "outputs": [
    {
     "name": "stdout",
     "output_type": "stream",
     "text": [
      "An error occurred: {code: Neo.ClientError.Security.Unauthorized} {message: The client is unauthorized due to authentication failure.}\n"
     ]
    }
   ],
   "source": [
    "from neo4j import GraphDatabase\n",
    "from neo4j.exceptions import ServiceUnavailable\n",
    "\n",
    "def connect_to_neo4j(uri=\"bolt://localhost:2123\", user=\"neo4j\", password=\"niklasniklaspwtem\"):\n",
    "    try:\n",
    "        # Create the driver\n",
    "        driver = GraphDatabase.driver(uri, auth=(user, password))\n",
    "        \n",
    "        # Verify the connection\n",
    "        with driver.session() as session:\n",
    "            result = session.run(\"RETURN 'Connected!' as message\")\n",
    "            print(result.single()['message'])\n",
    "            \n",
    "        return driver\n",
    "    \n",
    "    except ServiceUnavailable:\n",
    "        print(\"Failed to connect to Neo4j. Make sure the database is running.\")\n",
    "        return None\n",
    "    except Exception as e:\n",
    "        print(f\"An error occurred: {str(e)}\")\n",
    "        return None\n",
    "\n",
    "# Connect to the database\n",
    "driver = connect_to_neo4j(password=\"1234567890\")\n",
    "\n",
    "# Don't forget to close the driver when you're done\n",
    "if driver:\n",
    "    driver.close()"
   ]
  },
  {
   "cell_type": "code",
   "execution_count": null,
   "metadata": {},
   "outputs": [],
   "source": []
  },
  {
   "cell_type": "code",
   "execution_count": null,
   "metadata": {},
   "outputs": [],
   "source": []
  },
  {
   "cell_type": "code",
   "execution_count": 3,
   "metadata": {},
   "outputs": [
    {
     "name": "stderr",
     "output_type": "stream",
     "text": [
      "/home/nab/anaconda3/envs/pyeed_niklas/lib/python3.12/site-packages/transformers/modeling_utils.py:3479: FutureWarning: The `use_auth_token` argument is deprecated and will be removed in v5 of Transformers. Please use `token` instead.\n",
      "  warnings.warn(\n",
      "Some weights of EsmModel were not initialized from the model checkpoint at facebook/esm2_t33_650M_UR50D and are newly initialized: ['esm.pooler.dense.bias', 'esm.pooler.dense.weight']\n",
      "You should probably TRAIN this model on a down-stream task to be able to use it for predictions and inference.\n",
      "/home/nab/anaconda3/envs/pyeed_niklas/lib/python3.12/site-packages/transformers/tokenization_utils_base.py:2077: FutureWarning: The `use_auth_token` argument is deprecated and will be removed in v5 of Transformers. Please use `token` instead.\n",
      "  warnings.warn(\n"
     ]
    },
    {
     "name": "stdout",
     "output_type": "stream",
     "text": [
      "[[ 0.0142028  -0.00910573 -0.01854059 ...  0.02380231  0.00308922\n",
      "  -0.00295203]\n",
      " [-0.00080086  0.00021078 -0.00209417 ...  0.01293773  0.01800609\n",
      "   0.00211837]\n",
      " [ 0.01560119  0.00306283  0.00825493 ...  0.00882026  0.01818791\n",
      "  -0.02150113]\n",
      " ...\n",
      " [ 0.01973298  0.00275489 -0.00054867 ... -0.01560443  0.01923043\n",
      "   0.00694647]\n",
      " [ 0.01434401 -0.01296173 -0.01841157 ... -0.01217795  0.00770272\n",
      "   0.00501317]\n",
      " [ 0.00929134  0.02663751 -0.01983731 ... -0.01466107 -0.01553446\n",
      "   0.02172238]]\n",
      "[[ 0.00076523  0.00279567 -0.00162358 ...  0.00713985 -0.00858994\n",
      "  -0.00647934]\n",
      " [-0.000209    0.01204094  0.01753633 ...  0.00723459  0.01601353\n",
      "   0.02112885]\n",
      " [-0.0068271  -0.02380384 -0.00346624 ...  0.00838216  0.0001251\n",
      "   0.04243635]\n",
      " ...\n",
      " [-0.00140279  0.02693377 -0.01517223 ...  0.00075962 -0.0306487\n",
      "   0.03990513]\n",
      " [-0.00528439  0.00386792 -0.00534109 ...  0.00845299 -0.01491988\n",
      "   0.01154343]\n",
      " [ 0.01191642  0.00617199  0.00360093 ... -0.00015407 -0.01337884\n",
      "   0.00857108]]\n"
     ]
    },
    {
     "ename": "ValueError",
     "evalue": "operands could not be broadcast together with shapes (64,1280) (66,960) ",
     "output_type": "error",
     "traceback": [
      "\u001b[0;31m---------------------------------------------------------------------------\u001b[0m",
      "\u001b[0;31mValueError\u001b[0m                                Traceback (most recent call last)",
      "Cell \u001b[0;32mIn[3], line 8\u001b[0m\n\u001b[1;32m      5\u001b[0m \u001b[38;5;28mprint\u001b[39m(embedding_1)\n\u001b[1;32m      6\u001b[0m \u001b[38;5;28mprint\u001b[39m(embedding_2)\n\u001b[0;32m----> 8\u001b[0m \u001b[38;5;28mprint\u001b[39m(np\u001b[38;5;241m.\u001b[39mlinalg\u001b[38;5;241m.\u001b[39mnorm(\u001b[43membedding_1\u001b[49m\u001b[43m \u001b[49m\u001b[38;5;241;43m-\u001b[39;49m\u001b[43m \u001b[49m\u001b[43membedding_2\u001b[49m))\n",
      "\u001b[0;31mValueError\u001b[0m: operands could not be broadcast together with shapes (64,1280) (66,960) "
     ]
    }
   ],
   "source": [
    "et = EmbeddingTool()\n",
    "\n",
    "embedding_1 = et.calculate_single_sequence_embedding(sequence=\"MALWMRLLPLLALLALWGPDPAAALGYAAKALRIPGKGQARWLLPLLALLALWGPDPAAALGYA\")\n",
    "embedding_2 = et.calculate_single_sequence_embedding(sequence=\"MALWMRLLPLLALLALWGPDPAAALGYAAKALRIPGKGQARWLLPLLALLALWGPDPAAALGYA\", model_name=\"esmc_300m\")\n",
    "print(embedding_1)\n",
    "print(embedding_2)\n",
    "\n",
    "print(np.linalg.norm(embedding_1 - embedding_2))"
   ]
  },
  {
   "cell_type": "code",
   "execution_count": 1,
   "metadata": {},
   "outputs": [
    {
     "data": {
      "text/plain": [
       "True"
      ]
     },
     "execution_count": 1,
     "metadata": {},
     "output_type": "execute_result"
    }
   ],
   "source": [
    "a = \"VYKYTAQSLRHKRQLVAGLKNTSYNAVHWSQLAPEEQIRFWEDYEAGRATTFLVEPERKRTKRRRGEHSTKPKCENPSWYRPERYKALKGQLGHAYNRLVKKDPVTGEQSLRMRMSRHPFYVQKRTFVGRKYAFRPEKQRLLDAIWPVLVSFSDAGTHTVGMSVTRLAEEISPKDSEGHVIPELEVTVSRLSRLLAEQVRFGVLGVSEETMWDREHRQRLPRYVWITPAGWQMLGVDMVKLHEQQQKRLRESEIRQQLIREGVLREDEDISVHAARKRWYLQRSQDALKKRREKAAASKRANRLKKLPVDQQIYEMAEYLRKRLPPDEAYFCSDDHLKRLAIRELRQLELTLAAPPPH\"\n",
    "b = \"VYKYTAQSLRHKRQLVAGLKNTSYNAVHWSQLAPEEQIRFWEDYEAGRATTFLVEPERKRTKRRRGEHSTKPKCENPSWYRPERYKALKGQLGHAYNRLVKKDPVTGEQSLRMRMSRHPFYVQKRTFVGRKYAFRPEKQRLLDAIWPVLVSFSDAGTHTVGMSVTRLAEEISPKDSEGHVIPELEVTVSRLSRLLAEQVRFGVLGVSEETMWDREHRQRLPRYVWITPAGWQMLGVDMVKLHEQQQKRLRESEIRQQLIREGVLREDEDISVHAARKRWYLQRSQDALKKRREKAAASKRANRLKKLPVDQQIYEMAEYLRKRLPPDEAYFCSDDHLKRLAIRELRQLELTLAAPPPH\"\n",
    "a == b"
   ]
  },
  {
   "cell_type": "code",
   "execution_count": null,
   "metadata": {},
   "outputs": [],
   "source": []
  }
 ],
 "metadata": {
  "kernelspec": {
   "display_name": "pyeed_niklas",
   "language": "python",
   "name": "python3"
  },
  "language_info": {
   "codemirror_mode": {
    "name": "ipython",
    "version": 3
   },
   "file_extension": ".py",
   "mimetype": "text/x-python",
   "name": "python",
   "nbconvert_exporter": "python",
   "pygments_lexer": "ipython3",
   "version": "3.12.8"
  }
 },
 "nbformat": 4,
 "nbformat_minor": 2
}
